Workbook
Name a: '[1]Admin Nombres'!$F$28:$F$44
Name A_Transversal_Incidencia: 'Lista desplegable'!$I$2:$I$59
Name AA_Incidencia: 'Lista desplegable'!$AK$2:$AK$59
Name actividades4: [2]Hoja9!$F$3:$F$26
Name administrativo: [3]Actividad!$C$146:$D$150
Name B_Construyendo_Sostenibilidad: 'Lista desplegable'!$G$2:$G$59
Name BA_Adaptación_climática: 'Lista desplegable'!$AG$2:$AG$59
Name BB_Cuidado_del_medio_ambiente: 'Lista desplegable'!$AH$2:$AH$59
Name BC_Reducción_del_Riesgo_de_Desastres__RRD: 'Lista desplegable'!$AI$2:$AI$59
Name C_Niños_en_crisis: 'Lista desplegable'!$H$2:$H$59
Name CA_Niños_desplazados_en_crisis_protegidas: 'Lista desplegable'!$AJ$2:$AJ$59
Name CA_Proteccion_y_respuesta_lideradas_localmente: 'Lista desplegable'!$AJ$36:$AJ$60
Name Creciendo: [4]Actividad!$C$2:$D$17
Name Creciendo_Contigo: [3]Actividad!$C$2:$D$17
Name cuena: '[4]Admin Nombres'!$K$19:$K$48
Name cuentas: '[3]Admin Nombres'!$K$19:$K$48
Name D_Desarrollo_de_la_primera_infancia: 'Lista desplegable'!$C$2:$C$59
Name DA_Cuidado_receptivo: 'Lista desplegable'!$T$2:$T$59
Name DB_Atención_y_educación_de_la_primera_infancia_en_centros__ECCE: 'Lista desplegable'!$U$2:$U$59
Name Etapav1: [3]Actividad!$C$2:$C$17
Name etapav2: [3]Actividad!$C$18:$C$49
Name etapav23: [3]Actividad!$C$88:$C$116
Name etapav2a: [4]Actividad!$C$18:$C$49
Name etapav3: [3]Actividad!$C$50:$C$87
Name gestion_admin: [3]Actividad!$C$146:$C$150
Name gestion_p: [3]Actividad!$C$139:$C$145
Name GFC: 'Lista desplegable'!$AX$2:$AX$6
Name GFC_Fondo_Global_para_la_Niñez: 'Lista desplegable'!$AW$2
Name H_Salud: 'Lista desplegable'!$B$2:$B$59
Name HA_WASH: 'Lista desplegable'!$O$2:$O$59
Name HB_Nutrición: 'Lista desplegable'!$P$2:$P$59
Name HC_Salud_maternoinfantil: 'Lista desplegable'!$Q$2:$Q$59
Name HD_Salud_reproductiva: 'Lista desplegable'!$R$2:$R$59
Name HE__Enfermedad_infecciosa: 'Lista desplegable'!$S$2:$S$59
Name L_Medios_de_vida: 'Lista desplegable'!$F$2:$F$59
Name LA_Empoderamiento_económico_para_las_familias: 'Lista desplegable'!$AD$2:$AD$59
Name LB_Empoderamiento_económico_para_los_jóvenes: 'Lista desplegable'!$AE$2:$AE$59
Name LC_Seguridad_alimentaria: 'Lista desplegable'!$AF$2:$AF$59
Name M_Transversal_Salud_mental: 'Lista desplegable'!$J$2:$J$59
Name MA_Salud_mental_y_apoyo_psicosocial: 'Lista desplegable'!$AL$2:$AL$59
Name mecanismo: [3]Actividad!$C$117:$C$138
Name ML_Monitoreo: 'Lista desplegable'!$N$2:$N$59
Name ML_Monitoreo_y_soporte_técnico_del_programa: 'Lista desplegable'!$AP$2:$AP$59
Name modulo_ev1: '[3]Admin Nombres'!$A$28:$A$40
Name modulo_ev2: '[3]Admin Nombres'!$C$28:$C$40
Name modulo_ev3: '[3]Admin Nombres'!$E$28:$E$43
Name mqmc: [3]Actividad!$C$88:$D$116
Name mqmc_ev23: '[3]Admin Nombres'!$F$28:$F$44
Name nsyp: [3]Actividad!$C$18:$D$49
Name nsyp2: [4]Actividad!$C$18:$D$49
Name pacto: [3]Actividad!$C$50:$D$87
Name participantes: '[3]Admin Nombres'!$K$1:$K$15
Name patrocinio: [3]Actividad!$C$139:$D$145
Name PMA: 'Lista desplegable'!$AZ$2:$AZ$5
Name PMA_Programa_Mundial_de_Alimentos: 'Lista desplegable'!$AY$2
Name proteccion: [3]Actividad!$C$117:$D$138
Name R_Protección: 'Lista desplegable'!$E$2:$E$59
Name RA_Seguridad_en_línea: 'Lista desplegable'!$Z$2:$Z$59
Name RB_Trabajo_infantil: 'Lista desplegable'!$AA$2:$AA$59
Name RC_Prevención_y_respuesta_a_prácticas_nocivas: 'Lista desplegable'!$AB$2:$AB$59

Sheet Propuesta 2
A1: ACCION HONDURAS
A2: MATRIZ DE EVALUACION DE DESEMPEÑO DEL COLABORADOR
A4: Nombre y cargo del Colaborador: | H4: Jose Adalid Funes - Técnico de Desarrollo Comunitario | J4: Beyquer Odan Maldonado - Coordinador de Área | O4: Evaluador: | Q4: José Orlando Osorto Pérez - Director General
O5: VoBo RRHH | Q5: Jennifer Sabrina Romero Martínez - Especialista en RRHH
A7: Area | E7: Periodo evaluado | F7: Marco de Resultados | K7: Responsabilidades del colaborador | L7: Cantidad a Lograr | P7: Tiempo Definido (dias) | T7: Estandares de calidad (Escala de 10) | AA7: Nota Final
A8: Principal | B8: Transversal | C8: Responsable | D8: Forma de Ejecucion | F8: S | G8: SS | H8: ML | I8: Ext | L8: Programada | M8: Entregada | N8: Diferencia | O8: % | P8: Programado | Q8: Entregada | R8: Diferencia | S8: % | T8: Puntualidad | U8: Resolucion de Problemas | V8: Coordinaciión local | W8: Nivel de satisfacción de Grupos meta | X8: Nivel de preparación | Y8: Total Estandares (Nota max. 50) | Z8: %
A10: PROG | B10: MEAL | C10: Lider-Prog-EV1 | D10: Personal | F10: H_Salud | G10: HB_Nutrición | H10: HB041-01_Suplementos_nutricionales_para_niños_con_desnutrición_aguda_grave_o_desnutrición_aguda_moderada | I10: 1 | J10: DX | K10: Diseñar herramientas y protocolo para Dx.situacional de EV-1 | N10: =+L10-M10 -> 0 | O10: =IFERROR(IF(7<>0, M10*100/L10, IF(L10=M10, M10*100/L10, 0)), 0) -> 0 | R10: =+P10-Q10 -> 0 | S10: =IFERROR(IF(R10<>0, P10*100/Q10, IF(P10=Q10, P10*100/Q10, 0)), 0) -> 0 | Y10: =SUM(T10:X10) -> 0 | Z10: =+Y10*100/50 -> 0 | AA10: =+(S10+O10+Z10)/3 -> 0
A11: PROG | B11: MEAL | C11: Lider-Prog-EV2 | D11: Personal | F11: H_Salud | G11: HB_Nutrición | H11: HB041-01_Suplementos_nutricionales_para_niños_con_desnutrición_aguda_grave_o_desnutrición_aguda_moderada | I11: 1 | J11: DX | K11: Diseñar herramientas y protocolo para Dx.situacional de EV-2 | N11: =+L11-M11 -> 0 | O11: =IFERROR(IF(7<>0, M11*100/L11, IF(L11=M11, M11*100/L11, 0)), 0) -> 0 | R11: =+P11-Q11 -> 0 | S11: =IFERROR(IF(R11<>0, P11*100/Q11, IF(P11=Q11, P11*100/Q11, 0)), 0) -> 0 | Y11: =SUM(T11:X11) -> 0 | Z11: =+Y11*100/50 -> 0 | AA11: =+(S11+O11+Z11)/3 -> 0
A12: PROG | B12: MEAL | C12: Lider-Prog-EV3 | D12: Personal | F12: H_Salud | G12: HB_Nutrición | H12: HB041-01_Suplementos_nutricionales_para_niños_con_desnutrición_aguda_grave_o_desnutrición_aguda_moderada | I12: 1 | J12: DX | K12: Diseñar herramientas y protocolo para Dx.situacional de EV-3 | N12: =+L12-M12 -> 0 | O12: =IFERROR(IF(7<>0, M12*100/L12, IF(L12=M12, M12*100/L12, 0)), 0) -> 0 | R12: =+P12-Q12 -> 0 | S12: =IFERROR(IF(R12<>0, P12*100/Q12, IF(P12=Q12, P12*100/Q12, 0)), 0) -> 0 | Y12: =SUM(T12:X12) -> 0 | Z12: =+Y12*100/50 -> 0 | AA12: =+(S12+O12+Z12)/3 -> 0
A13: PROG | B13: MEAL | C13: Red de Madres guia | D13: Apoyo voluntario | F13: H_Salud | G13: HB_Nutrición | H13: HB041-01_Suplementos_nutricionales_para_niños_con_desnutrición_aguda_grave_o_desnutrición_aguda_moderada | I13: 1 | J13: DX | K13: Levantar Diagnostico situacional de primera infancia | L13: 500 | M13: 410 | N13: =+L13-M13 -> 90 | O13: =IFERROR(IF(7<>0, M13*100/L13, IF(L13=M13, M13*100/L13, 0)), 0) -> 82 | P13: 15 | Q13: 22 | R13: =+P13-Q13 -> -7 | S13: =IFERROR(IF(R13<>0, P13*100/Q13, IF(P13=Q13, P13*100/Q13, 0)), 0) -> 68.181818 | T13: 9 | U13: 7 | V13: 10 | W13: 8 | X13: 10 | Y13: =SUM(T13:X13) -> 44 | Z13: =+Y13*100/50 -> 88 | AA13: =+(S13+O13+Z13)/3 -> 79.393939
A14: PROG | B14: MEAL | C14: Red de Docentes | D14: Apoyo voluntario | J14: DX | K14: Levantar diagnóstico situacional de NN en el Centro Educativo. | N14: =+L14-M14 -> 0 | O14: =IFERROR(IF(7<>0, M14*100/L14, IF(L14=M14, M14*100/L14, 0)), 0) -> 0 | R14: =+P14-Q14 -> 0 | S14: =IFERROR(IF(R14<>0, P14*100/Q14, IF(P14=Q14, P14*100/Q14, 0)), 0) -> 0 | Y14: =SUM(T14:X14) -> 0 | Z14: =+Y14*100/50 -> 0 | AA14: =+(S14+O14+Z14)/3 -> 0
A15: PROG | B15: MEAL | C15: Red de Apoyo Juvenil | D15: Apoyo voluntario | J15: DX | K15: Levantar diagnóstico aptitudinal y de intereses de AJ en las comunidades | N15: =+L15-M15 -> 0 | O15: =IFERROR(IF(7<>0, M15*100/L15, IF(L15=M15, M15*100/L15, 0)), 0) -> 0 | R15: =+P15-Q15 -> 0 | S15: =IFERROR(IF(R15<>0, P15*100/Q15, IF(P15=Q15, P15*100/Q15, 0)), 0) -> 0 | Y15: =SUM(T15:X15) -> 0 | Z15: =+Y15*100/50 -> 0 | AA15: =+(S15+O15+Z15)/3 -> 0
A16: PROG | B16: MEAL | C16: Lider-Prog-EV1 | D16: Personal | J16: DX | K16: Procesar y limpiar datos de Dx para elaborar informe sobre situacion EV-1 | N16: =+L16-M16 -> 0 | O16: =IFERROR(IF(7<>0, M16*100/L16, IF(L16=M16, M16*100/L16, 0)), 0) -> 0 | R16: =+P16-Q16 -> 0 | S16: =IFERROR(IF(R16<>0, P16*100/Q16, IF(P16=Q16, P16*100/Q16, 0)), 0) -> 0 | Y16: =SUM(T16:X16) -> 0 | Z16: =+Y16*100/50 -> 0 | AA16: =+(S16+O16+Z16)/3 -> 0
A17: PROG | B17: MEAL | C17: Lider-Prog-EV2 | D17: Personal | J17: DX | K17: Procesar y limpiar datos de Dx para elaborar informe sobre situacion EV-2 | N17: =+L17-M17 -> 0 | O17: =IFERROR(IF(7<>0, M17*100/L17, IF(L17=M17, M17*100/L17, 0)), 0) -> 0 | R17: =+P17-Q17 -> 0 | S17: =IFERROR(IF(R17<>0, P17*100/Q17, IF(P17=Q17, P17*100/Q17, 0)), 0) -> 0 | Y17: =SUM(T17:X17) -> 0 | Z17: =+Y17*100/50 -> 0 | AA17: =+(S17+O17+Z17)/3 -> 0
A18: PROG | B18: MEAL | C18: Lider-Prog-EV3 | D18: Personal | J18: DX | K18: Procesar y limpiar datos de Dx para elaborar informe sobre situacion EV-3 | N18: =+L18-M18 -> 0 | O18: =IFERROR(IF(7<>0, M18*100/L18, IF(L18=M18, M18*100/L18, 0)), 0) -> 0 | R18: =+P18-Q18 -> 0 | S18: =IFERROR(IF(R18<>0, P18*100/Q18, IF(P18=Q18, P18*100/Q18, 0)), 0) -> 0 | Y18: =SUM(T18:X18) -> 0 | Z18: =+Y18*100/50 -> 0 | AA18: =+(S18+O18+Z18)/3 -> 0
A19: PROG | B19: MEAL | C19: Lider-Prog-EV1 | D19: Sinergia Equipo | J19: DX | K19: Organizar evento de socialización de resultados de Dx.situacional EV-1 (apoyos) | N19: =+L19-M19 -> 0 | O19: =IFERROR(IF(7<>0, M19*100/L19, IF(L19=M19, M19*100/L19, 0)), 0) -> 0 | R19: =+P19-Q19 -> 0 | S19: =IFERROR(IF(R19<>0, P19*100/Q19, IF(P19=Q19, P19*100/Q19, 0)), 0) -> 0 | Y19: =SUM(T19:X19) -> 0 | Z19: =+Y19*100/50 -> 0 | AA19: =+(S19+O19+Z19)/3 -> 0
A20: PROG | B20: MEAL | C20: Lider-Prog-EV2 | D20: Sinergia Equipo | J20: DX | K20: Organizar evento de socialización de resultados de Dx.situacional EV-2 (apoyos) | N20: =+L20-M20 -> 0 | O20: =IFERROR(IF(7<>0, M20*100/L20, IF(L20=M20, M20*100/L20, 0)), 0) -> 0 | R20: =+P20-Q20 -> 0 | S20: =IFERROR(IF(R20<>0, P20*100/Q20, IF(P20=Q20, P20*100/Q20, 0)), 0) -> 0 | Y20: =SUM(T20:X20) -> 0 | Z20: =+Y20*100/50 -> 0 | AA20: =+(S20+O20+Z20)/3 -> 0
A21: PROG | B21: MEAL | C21: Lider-Prog-EV3 | D21: Sinergia Equipo | J21: DX | K21: Organizar evento de socialización de resultados de Dx.situacional EV-3 (apoyos) | N21: =+L21-M21 -> 0 | O21: =IFERROR(IF(7<>0, M21*100/L21, IF(L21=M21, M21*100/L21, 0)), 0) -> 0 | R21: =+P21-Q21 -> 0 | S21: =IFERROR(IF(R21<>0, P21*100/Q21, IF(P21=Q21, P21*100/Q21, 0)), 0) -> 0 | Y21: =SUM(T21:X21) -> 0 | Z21: =+Y21*100/50 -> 0 | AA21: =+(S21+O21+Z21)/3 -> 0
A22: PROG | B22: MEAL | C22: Lider-Prog-EV1 | D22: Sinergia Equipo | J22: DX | K22: Desarrollar evento de socialización de resultados de Dx.situacional EV-1 | N22: =+L22-M22 -> 0 | O22: =IFERROR(IF(7<>0, M22*100/L22, IF(L22=M22, M22*100/L22, 0)), 0) -> 0 | R22: =+P22-Q22 -> 0 | S22: =IFERROR(IF(R22<>0, P22*100/Q22, IF(P22=Q22, P22*100/Q22, 0)), 0) -> 0 | Y22: =SUM(T22:X22) -> 0 | Z22: =+Y22*100/50 -> 0 | AA22: =+(S22+O22+Z22)/3 -> 0
A23: PROG | B23: MEAL | C23: Lider-Prog-EV2 | D23: Sinergia Equipo | J23: DX | K23: Desarrollar evento de socialización de resultados de Dx.situacional EV-2 | N23: =+L23-M23 -> 0 | O23: =IFERROR(IF(7<>0, M23*100/L23, IF(L23=M23, M23*100/L23, 0)), 0) -> 0 | R23: =+P23-Q23 -> 0 | S23: =IFERROR(IF(R23<>0, P23*100/Q23, IF(P23=Q23, P23*100/Q23, 0)), 0) -> 0 | Y23: =SUM(T23:X23) -> 0 | Z23: =+Y23*100/50 -> 0 | AA23: =+(S23+O23+Z23)/3 -> 0
A24: PROG | B24: MEAL | C24: Lider-Prog-EV3 | D24: Sinergia Equipo | J24: DX | K24: Desarrollar evento de socialización de resultados de Dx.situacional EV-3 | N24: =+L24-M24 -> 0 | O24: =IFERROR(IF(7<>0, M24*100/L24, IF(L24=M24, M24*100/L24, 0)), 0) -> 0 | R24: =+P24-Q24 -> 0 | S24: =IFERROR(IF(R24<>0, P24*100/Q24, IF(P24=Q24, P24*100/Q24, 0)), 0) -> 0 | Y24: =SUM(T24:X24) -> 0 | Z24: =+Y24*100/50 -> 0 | AA24: =+(S24+O24+Z24)/3 -> 0
A25: PROG | C25: Lider-Prog-EV1 | D25: Personal | J25: CI | K25: Buscar y representar a AH en alianzas de coordinacion con socios Proy-EV-1 | N25: =+L25-M25 -> 0 | O25: =IFERROR(IF(7<>0, M25*100/L25, IF(L25=M25, M25*100/L25, 0)), 0) -> 0 | R25: =+P25-Q25 -> 0 | S25: =IFERROR(IF(R25<>0, P25*100/Q25, IF(P25=Q25, P25*100/Q25, 0)), 0) -> 0 | Y25: =SUM(T25:X25) -> 0 | Z25: =+Y25*100/50 -> 0 | AA25: =+(S25+O25+Z25)/3 -> 0
A26: PROG | C26: Lider-Prog-EV2 | D26: Personal | J26: CI | K26: Buscar y representar a AH en alianzas de coordinacion con socios Proy-EV-2 | N26: =+L26-M26 -> 0 | O26: =IFERROR(IF(7<>0, M26*100/L26, IF(L26=M26, M26*100/L26, 0)), 0) -> 0 | R26: =+P26-Q26 -> 0 | S26: =IFERROR(IF(R26<>0, P26*100/Q26, IF(P26=Q26, P26*100/Q26, 0)), 0) -> 0 | Y26: =SUM(T26:X26) -> 0 | Z26: =+Y26*100/50 -> 0 | AA26: =+(S26+O26+Z26)/3 -> 0
A27: PROG | C27: Lider-Prog-EV3 | D27: Personal | J27: CI | K27: Buscar y representar a AH en alianzas de coordinacion con socios Proy-EV-3 | N27: =+L27-M27 -> 0 | O27: =IFERROR(IF(7<>0, M27*100/L27, IF(L27=M27, M27*100/L27, 0)), 0) -> 0 | R27: =+P27-Q27 -> 0 | S27: =IFERROR(IF(R27<>0, P27*100/Q27, IF(P27=Q27, P27*100/Q27, 0)), 0) -> 0 | Y27: =SUM(T27:X27) -> 0 | Z27: =+Y27*100/50 -> 0 | AA27: =+(S27+O27+Z27)/3 -> 0
A28: PROT | C28: Lider-Prot-Incid | D28: Personal | J28: CI | K28: Buscar y representar a AH en alianzas de coordinacion con socios Proteccion e Inc | N28: =+L28-M28 -> 0 | O28: =IFERROR(IF(7<>0, M28*100/L28, IF(L28=M28, M28*100/L28, 0)), 0) -> 0 | R28: =+P28-Q28 -> 0 | S28: =IFERROR(IF(R28<>0, P28*100/Q28, IF(P28=Q28, P28*100/Q28, 0)), 0) -> 0 | Y28: =SUM(T28:X28) -> 0 | Z28: =+Y28*100/50 -> 0 | AA28: =+(S28+O28+Z28)/3 -> 0
A29: PROG | C29: Lider-Prog-EV1 | D29: Personal | K29: Definir contenidos y lineamientos para organizar y coordinar red de madres guia | N29: =+L29-M29 -> 0 | O29: =IFERROR(IF(7<>0, M29*100/L29, IF(L29=M29, M29*100/L29, 0)), 0) -> 0 | R29: =+P29-Q29 -> 0 | S29: =IFERROR(IF(R29<>0, P29*100/Q29, IF(P29=Q29, P29*100/Q29, 0)), 0) -> 0 | Y29: =SUM(T29:X29) -> 0 | Z29: =+Y29*100/50 -> 0 | AA29: =+(S29+O29+Z29)/3 -> 0
A30: PROT | C30: Lider-Prot-Incid | D30: Personal | K30: Definir contenidos y lineamientos para organizar y coordinar MPBC | N30: =+L30-M30 -> 0 | O30: =IFERROR(IF(7<>0, M30*100/L30, IF(L30=M30, M30*100/L30, 0)), 0) -> 0 | R30: =+P30-Q30 -> 0 | S30: =IFERROR(IF(R30<>0, P30*100/Q30, IF(P30=Q30, P30*100/Q30, 0)), 0) -> 0 | Y30: =SUM(T30:X30) -> 0 | Z30: =+Y30*100/50 -> 0 | AA30: =+(S30+O30+Z30)/3 -> 0
A31: PROG | C31: Lider-Prog-EV2 | D31: Personal | K31: Definir contenidos y lineamientos para organizar y coordinar red Educativa | N31: =+L31-M31 -> 0 | O31: =IFERROR(IF(7<>0, M31*100/L31, IF(L31=M31, M31*100/L31, 0)), 0) -> 0 | R31: =+P31-Q31 -> 0 | S31: =IFERROR(IF(R31<>0, P31*100/Q31, IF(P31=Q31, P31*100/Q31, 0)), 0) -> 0 | Y31: =SUM(T31:X31) -> 0 | Z31: =+Y31*100/50 -> 0 | AA31: =+(S31+O31+Z31)/3 -> 0
A32: PROG | C32: Lider-Prog-EV3 | D32: Personal | K32: Definir contenidos y lineamientos para organizar y coordinar red de apoyo juvenil | N32: =+L32-M32 -> 0 | O32: =IFERROR(IF(7<>0, M32*100/L32, IF(L32=M32, M32*100/L32, 0)), 0) -> 0 | R32: =+P32-Q32 -> 0 | S32: =IFERROR(IF(R32<>0, P32*100/Q32, IF(P32=Q32, P32*100/Q32, 0)), 0) -> 0 | Y32: =SUM(T32:X32) -> 0 | Z32: =+Y32*100/50 -> 0 | AA32: =+(S32+O32+Z32)/3 -> 0
A33: PROG | C33: Lider-Prog-EV1 | D33: Por Producto | K33: Elaboracion de material didactico para Proy- EV-1, según Branding (contrato) | N33: =+L33-M33 -> 0 | O33: =IFERROR(IF(7<>0, M33*100/L33, IF(L33=M33, M33*100/L33, 0)), 0) -> 0 | R33: =+P33-Q33 -> 0 | S33: =IFERROR(IF(R33<>0, P33*100/Q33, IF(P33=Q33, P33*100/Q33, 0)), 0) -> 0 | Y33: =SUM(T33:X33) -> 0 | Z33: =+Y33*100/50 -> 0 | AA33: =+(S33+O33+Z33)/3 -> 0
A34: PROG | C34: Lider-Prog-EV2 | D34: Por Producto | K34: Elaboracion de material didactico para Proy- EV-2, según Branding (contrato) | N34: =+L34-M34 -> 0 | O34: =IFERROR(IF(7<>0, M34*100/L34, IF(L34=M34, M34*100/L34, 0)), 0) -> 0 | R34: =+P34-Q34 -> 0 | S34: =IFERROR(IF(R34<>0, P34*100/Q34, IF(P34=Q34, P34*100/Q34, 0)), 0) -> 0 | Y34: =SUM(T34:X34) -> 0 | Z34: =+Y34*100/50 -> 0 | AA34: =+(S34+O34+Z34)/3 -> 0
A35: PROG | C35: Lider-Prog-EV3 | D35: Por Producto | K35: Elaboracion de material didactico para Proy- EV-3, según Branding (contrato) | N35: =+L35-M35 -> 0 | O35: =IFERROR(IF(7<>0, M35*100/L35, IF(L35=M35, M35*100/L35, 0)), 0) -> 0 | R35: =+P35-Q35 -> 0 | S35: =IFERROR(IF(R35<>0, P35*100/Q35, IF(P35=Q35, P35*100/Q35, 0)), 0) -> 0 | Y35: =SUM(T35:X35) -> 0 | Z35: =+Y35*100/50 -> 0 | AA35: =+(S35+O35+Z35)/3 -> 0
A36: PROT | C36: Lider-Prot-Incid | D36: Por Producto | K36: Elaboracion de material didactico para Proteccion e Incidencia (contrato) | N36: =+L36-M36 -> 0 | O36: =IFERROR(IF(7<>0, M36*100/L36, IF(L36=M36, M36*100/L36, 0)), 0) -> 0 | R36: =+P36-Q36 -> 0 | S36: =IFERROR(IF(R36<>0, P36*100/Q36, IF(P36=Q36, P36*100/Q36, 0)), 0) -> 0 | Y36: =SUM(T36:X36) -> 0 | Z36: =+Y36*100/50 -> 0 | AA36: =+(S36+O36+Z36)/3 -> 0
A37: PROG | C37: Lider-Prog-EV1 | D37: Personal | K37: Organizar, coordinar y dar asistencia tecnica a Red de madres guía. | L37: 4 | M37: 4 | N37: =+L37-M37 -> 0 | O37: =IFERROR(IF(7<>0, M37*100/L37, IF(L37=M37, M37*100/L37, 0)), 0) -> 100 | P37: 5 | Q37: 5 | R37: =+P37-Q37 -> 0 | S37: =IFERROR(IF(R37<>0, P37*100/Q37, IF(P37=Q37, P37*100/Q37, 0)), 0) -> 100 | T37: 8 | U37: 6 | V37: 6 | W37: 8 | X37: 8 | Y37: =SUM(T37:X37) -> 36 | Z37: =+Y37*100/50 -> 72 | AA37: =+(S37+O37+Z37)/3 -> 90.666667
A38: PROT | B38: PROG | C38: Lider-Prot-Incid | D38: Personal | K38: Organizar, capacitar y monitorear plan de acción de los MPBC | N38: =+L38-M38 -> 0 | O38: =IFERROR(IF(7<>0, M38*100/L38, IF(L38=M38, M38*100/L38, 0)), 0) -> 0 | R38: =+P38-Q38 -> 0 | S38: =IFERROR(IF(R38<>0, P38*100/Q38, IF(P38=Q38, P38*100/Q38, 0)), 0) -> 0 | Y38: =SUM(T38:X38) -> 0 | Z38: =+Y38*100/50 -> 0 | AA38: =+(S38+O38+Z38)/3 -> 0
A39: PROG | C39: Lider-Prog-EV2 | D39: Personal | K39: Organizar, coordinar y dar asistencia tecnica a Red Educativa-APF y docente. | N39: =+L39-M39 -> 0 | O39: =IFERROR(IF(7<>0, M39*100/L39, IF(L39=M39, M39*100/L39, 0)), 0) -> 0 | R39: =+P39-Q39 -> 0 | S39: =IFERROR(IF(R39<>0, P39*100/Q39, IF(P39=Q39, P39*100/Q39, 0)), 0) -> 0 | Y39: =SUM(T39:X39) -> 0 | Z39: =+Y39*100/50 -> 0 | AA39: =+(S39+O39+Z39)/3 -> 0
A40: PROG | C40: Lider-Prog-EV3 | D40: Personal | K40: Organizar, coordinar y dar asistencia tecnica a Red de Apoyo Juvenil | N40: =+L40-M40 -> 0 | O40: =IFERROR(IF(7<>0, M40*100/L40, IF(L40=M40, M40*100/L40, 0)), 0) -> 0 | R40: =+P40-Q40 -> 0 | S40: =IFERROR(IF(R40<>0, P40*100/Q40, IF(P40=Q40, P40*100/Q40, 0)), 0) -> 0 | Y40: =SUM(T40:X40) -> 0 | Z40: =+Y40*100/50 -> 0 | AA40: =+(S40+O40+Z40)/3 -> 0
A41: PROG | B41: RRHH | C41: Lider-Prog-EV1 | D41: Personal | K41: Diseñar plan de formacion virtual-presencial para ET y red en EV-1 | N41: =+L41-M41 -> 0 | O41: =IFERROR(IF(7<>0, M41*100/L41, IF(L41=M41, M41*100/L41, 0)), 0) -> 0 | R41: =+P41-Q41 -> 0 | S41: =IFERROR(IF(R41<>0, P41*100/Q41, IF(P41=Q41, P41*100/Q41, 0)), 0) -> 0 | Y41: =SUM(T41:X41) -> 0 | Z41: =+Y41*100/50 -> 0 | AA41: =+(S41+O41+Z41)/3 -> 0
A42: PROT | C42: Lider-Prot-Incid | D42: Personal | K42: Diseñar e implementar plan de formacion virtual-presencial para ET y MPBC | N42: =+L42-M42 -> 0 | O42: =IFERROR(IF(7<>0, M42*100/L42, IF(L42=M42, M42*100/L42, 0)), 0) -> 0 | R42: =+P42-Q42 -> 0 | S42: =IFERROR(IF(R42<>0, P42*100/Q42, IF(P42=Q42, P42*100/Q42, 0)), 0) -> 0 | Y42: =SUM(T42:X42) -> 0 | Z42: =+Y42*100/50 -> 0 | AA42: =+(S42+O42+Z42)/3 -> 0
A43: PROG | B43: RRHH | C43: Lider-Prog-EV2 | D43: Personal | K43: Diseñar plan de formacion virtual-presencial para ET y Red en EV-2 | N43: =+L43-M43 -> 0 | O43: =IFERROR(IF(7<>0, M43*100/L43, IF(L43=M43, M43*100/L43, 0)), 0) -> 0 | R43: =+P43-Q43 -> 0 | S43: =IFERROR(IF(R43<>0, P43*100/Q43, IF(P43=Q43, P43*100/Q43, 0)), 0) -> 0 | Y43: =SUM(T43:X43) -> 0 | Z43: =+Y43*100/50 -> 0 | AA43: =+(S43+O43+Z43)/3 -> 0
...

Sheet David
A1: ACCION HONDURAS
A2: MATRIZ DE EVALUACION DE DESEMPEÑO DEL COLABORADOR
A4: Nombre y cargo del Colaborador: | G4: Jose Adalid Funes - Técnico de Desarrollo Comunitario | I4: David Alonzo Ramos - Técnico de Desarrollo Comunitario | M4: Evaluador: | O4: Edwing Armando Lopez Esteves - Lider de Programa EV-3
M5: VoBo RRHH | O5: Jennifer Sabrina Romero Martínez - Especialista en RRHH
A7: Area | D7: Periodo evaluado | E7: Marco de Resultados | I7: Responsabilidades del colaborador | J7: Cantidad a Lograr | N7: Tiempo Definido (dias) | R7: Estandares de calidad (Escala de 10) | Y7: Nota Final
A8: Principal | B8: Transversal | C8: Responsable | E8: S | F8: SS | G8: ML | H8: Ext | J8: Programada | K8: Entregada | L8: Diferencia | M8: % | N8: Programado | O8: Entregada | P8: Diferencia | Q8: % | R8: Puntualidad | S8: Resolucion de Problemas | T8: Coordinaciión local | U8: Nivel de satisfacción de Grupos meta | V8: Nivel de preparación | W8: Total Estandares (Nota max. 50) | X8: %
A10: PROG | B10: MEAL | C10: Lider-Prog-EV1 | E10: H_Salud | F10: HB_Nutrición | G10: HB041-01_Suplementos_nutricionales_para_niños_con_desnutrición_aguda_grave_o_desnutrición_aguda_moderada | H10: 1 | I10: Diseñar herramientas y protocolo para Dx.situacional de EV-1 | L10: =+J10-K10 -> 0 | M10: =IFERROR(IF(7<>0, K10*100/J10, IF(J10=K10, K10*100/J10, 0)), 0) -> 0 | P10: =+N10-O10 -> 0 | Q10: =IFERROR(IF(P10<>0, N10*100/O10, IF(N10=O10, N10*100/O10, 0)), 0) -> 0 | W10: =SUM(R10:V10) -> 0 | X10: =+W10*100/50 -> 0 | Y10: =+(Q10+M10+X10)/3 -> 0
A11: PROG | B11: MEAL | C11: Lider-Prog-EV2 | E11: H_Salud | F11: HB_Nutrición | G11: HB041-01_Suplementos_nutricionales_para_niños_con_desnutrición_aguda_grave_o_desnutrición_aguda_moderada | H11: 1 | I11: Diseñar herramientas y protocolo para Dx.situacional de EV-2 | L11: =+J11-K11 -> 0 | M11: =IFERROR(IF(7<>0, K11*100/J11, IF(J11=K11, K11*100/J11, 0)), 0) -> 0 | P11: =+N11-O11 -> 0 | Q11: =IFERROR(IF(P11<>0, N11*100/O11, IF(N11=O11, N11*100/O11, 0)), 0) -> 0 | W11: =SUM(R11:V11) -> 0 | X11: =+W11*100/50 -> 0 | Y11: =+(Q11+M11+X11)/3 -> 0
A12: PROG | B12: MEAL | C12: Lider-Prog-EV3 | E12: H_Salud | F12: HB_Nutrición | G12: HB041-01_Suplementos_nutricionales_para_niños_con_desnutrición_aguda_grave_o_desnutrición_aguda_moderada | H12: 1 | I12: Diseñar herramientas y protocolo para Dx.situacional de EV-3 | L12: =+J12-K12 -> 0 | M12: =IFERROR(IF(7<>0, K12*100/J12, IF(J12=K12, K12*100/J12, 0)), 0) -> 0 | P12: =+N12-O12 -> 0 | Q12: =IFERROR(IF(P12<>0, N12*100/O12, IF(N12=O12, N12*100/O12, 0)), 0) -> 0 | W12: =SUM(R12:V12) -> 0 | X12: =+W12*100/50 -> 0 | Y12: =+(Q12+M12+X12)/3 -> 0
A13: PROG | B13: MEAL | C13: Tecn-Prog-EV-1 | E13: H_Salud | F13: HB_Nutrición | G13: HB041-01_Suplementos_nutricionales_para_niños_con_desnutrición_aguda_grave_o_desnutrición_aguda_moderada | H13: 1 | I13: Levantar Diagnostico situacional de primera infancia | J13: 500 | K13: 410 | L13: =+J13-K13 -> 90 | M13: =IFERROR(IF(7<>0, K13*100/J13, IF(J13=K13, K13*100/J13, 0)), 0) -> 82 | N13: 15 | O13: 22 | P13: =+N13-O13 -> -7 | Q13: =IFERROR(IF(P13<>0, N13*100/O13, IF(N13=O13, N13*100/O13, 0)), 0) -> 68.181818 | R13: 9 | S13: 7 | T13: 10 | U13: 8 | V13: 10 | W13: =SUM(R13:V13) -> 44 | X13: =+W13*100/50 -> 88 | Y13: =+(Q13+M13+X13)/3 -> 79.393939
A14: PROG | B14: MEAL | C14: Tecn-Prog-EV-2 | I14: Levantar diagnóstico situacional de NN en el Centro Educativo. | L14: =+J14-K14 -> 0 | M14: =IFERROR(IF(7<>0, K14*100/J14, IF(J14=K14, K14*100/J14, 0)), 0) -> 0 | P14: =+N14-O14 -> 0 | Q14: =IFERROR(IF(P14<>0, N14*100/O14, IF(N14=O14, N14*100/O14, 0)), 0) -> 0 | W14: =SUM(R14:V14) -> 0 | X14: =+W14*100/50 -> 0 | Y14: =+(Q14+M14+X14)/3 -> 0
A15: PROG | B15: MEAL | C15: Tecn-Prog-EV-3 | I15: Levantar diagnóstico aptitudinal y de intereses de AJ en las comunidades | L15: =+J15-K15 -> 0 | M15: =IFERROR(IF(7<>0, K15*100/J15, IF(J15=K15, K15*100/J15, 0)), 0) -> 0 | P15: =+N15-O15 -> 0 | Q15: =IFERROR(IF(P15<>0, N15*100/O15, IF(N15=O15, N15*100/O15, 0)), 0) -> 0 | W15: =SUM(R15:V15) -> 0 | X15: =+W15*100/50 -> 0 | Y15: =+(Q15+M15+X15)/3 -> 0
A16: PROG | B16: MEAL | C16: Lider-Prog-EV1 | I16: Procesar y limpiar datos de Dx para elaborar informe sobre situacion EV-1 | L16: =+J16-K16 -> 0 | M16: =IFERROR(IF(7<>0, K16*100/J16, IF(J16=K16, K16*100/J16, 0)), 0) -> 0 | P16: =+N16-O16 -> 0 | Q16: =IFERROR(IF(P16<>0, N16*100/O16, IF(N16=O16, N16*100/O16, 0)), 0) -> 0 | W16: =SUM(R16:V16) -> 0 | X16: =+W16*100/50 -> 0 | Y16: =+(Q16+M16+X16)/3 -> 0
A17: PROG | B17: MEAL | C17: Lider-Prog-EV2 | I17: Procesar y limpiar datos de Dx para elaborar informe sobre situacion EV-2 | L17: =+J17-K17 -> 0 | M17: =IFERROR(IF(7<>0, K17*100/J17, IF(J17=K17, K17*100/J17, 0)), 0) -> 0 | P17: =+N17-O17 -> 0 | Q17: =IFERROR(IF(P17<>0, N17*100/O17, IF(N17=O17, N17*100/O17, 0)), 0) -> 0 | W17: =SUM(R17:V17) -> 0 | X17: =+W17*100/50 -> 0 | Y17: =+(Q17+M17+X17)/3 -> 0
A18: PROG | B18: MEAL | C18: Lider-Prog-EV3 | I18: Procesar y limpiar datos de Dx para elaborar informe sobre situacion EV-3 | L18: =+J18-K18 -> 0 | M18: =IFERROR(IF(7<>0, K18*100/J18, IF(J18=K18, K18*100/J18, 0)), 0) -> 0 | P18: =+N18-O18 -> 0 | Q18: =IFERROR(IF(P18<>0, N18*100/O18, IF(N18=O18, N18*100/O18, 0)), 0) -> 0 | W18: =SUM(R18:V18) -> 0 | X18: =+W18*100/50 -> 0 | Y18: =+(Q18+M18+X18)/3 -> 0
A19: PROG | B19: MEAL | C19: Tecn-Prog-EV-1 | I19: Organizar evento de socialización de resultados de Dx.situacional EV-1 | L19: =+J19-K19 -> 0 | M19: =IFERROR(IF(7<>0, K19*100/J19, IF(J19=K19, K19*100/J19, 0)), 0) -> 0 | P19: =+N19-O19 -> 0 | Q19: =IFERROR(IF(P19<>0, N19*100/O19, IF(N19=O19, N19*100/O19, 0)), 0) -> 0 | W19: =SUM(R19:V19) -> 0 | X19: =+W19*100/50 -> 0 | Y19: =+(Q19+M19+X19)/3 -> 0
A20: PROG | B20: MEAL | C20: Tecn-Prog-EV-2 | I20: Organizar evento de socialización de resultados de Dx.situacional EV-2 | L20: =+J20-K20 -> 0 | M20: =IFERROR(IF(7<>0, K20*100/J20, IF(J20=K20, K20*100/J20, 0)), 0) -> 0 | P20: =+N20-O20 -> 0 | Q20: =IFERROR(IF(P20<>0, N20*100/O20, IF(N20=O20, N20*100/O20, 0)), 0) -> 0 | W20: =SUM(R20:V20) -> 0 | X20: =+W20*100/50 -> 0 | Y20: =+(Q20+M20+X20)/3 -> 0
A21: PROG | B21: MEAL | C21: Tecn-Prog-EV-3 | I21: Organizar evento de socialización de resultados de Dx.situacional EV-3 | L21: =+J21-K21 -> 0 | M21: =IFERROR(IF(7<>0, K21*100/J21, IF(J21=K21, K21*100/J21, 0)), 0) -> 0 | P21: =+N21-O21 -> 0 | Q21: =IFERROR(IF(P21<>0, N21*100/O21, IF(N21=O21, N21*100/O21, 0)), 0) -> 0 | W21: =SUM(R21:V21) -> 0 | X21: =+W21*100/50 -> 0 | Y21: =+(Q21+M21+X21)/3 -> 0
A22: PROG | B22: MEAL | C22: Lider-Prog-EV1 | I22: Desarrollar evento de socialización de resultados de Dx.situacional EV-1 | L22: =+J22-K22 -> 0 | M22: =IFERROR(IF(7<>0, K22*100/J22, IF(J22=K22, K22*100/J22, 0)), 0) -> 0 | P22: =+N22-O22 -> 0 | Q22: =IFERROR(IF(P22<>0, N22*100/O22, IF(N22=O22, N22*100/O22, 0)), 0) -> 0 | W22: =SUM(R22:V22) -> 0 | X22: =+W22*100/50 -> 0 | Y22: =+(Q22+M22+X22)/3 -> 0
A23: PROG | B23: MEAL | C23: Lider-Prog-EV2 | I23: Desarrollar evento de socialización de resultados de Dx.situacional EV-2 | L23: =+J23-K23 -> 0 | M23: =IFERROR(IF(7<>0, K23*100/J23, IF(J23=K23, K23*100/J23, 0)), 0) -> 0 | P23: =+N23-O23 -> 0 | Q23: =IFERROR(IF(P23<>0, N23*100/O23, IF(N23=O23, N23*100/O23, 0)), 0) -> 0 | W23: =SUM(R23:V23) -> 0 | X23: =+W23*100/50 -> 0 | Y23: =+(Q23+M23+X23)/3 -> 0
A24: PROG | B24: MEAL | C24: Lider-Prog-EV3 | I24: Desarrollar evento de socialización de resultados de Dx.situacional EV-3 | L24: =+J24-K24 -> 0 | M24: =IFERROR(IF(7<>0, K24*100/J24, IF(J24=K24, K24*100/J24, 0)), 0) -> 0 | P24: =+N24-O24 -> 0 | Q24: =IFERROR(IF(P24<>0, N24*100/O24, IF(N24=O24, N24*100/O24, 0)), 0) -> 0 | W24: =SUM(R24:V24) -> 0 | X24: =+W24*100/50 -> 0 | Y24: =+(Q24+M24+X24)/3 -> 0
A25: PROG | C25: Lider-Prog-EV1 | I25: Buscar y representar a AH en alianzas de coordinacion con socios Proy-EV-1 | L25: =+J25-K25 -> 0 | M25: =IFERROR(IF(7<>0, K25*100/J25, IF(J25=K25, K25*100/J25, 0)), 0) -> 0 | P25: =+N25-O25 -> 0 | Q25: =IFERROR(IF(P25<>0, N25*100/O25, IF(N25=O25, N25*100/O25, 0)), 0) -> 0 | W25: =SUM(R25:V25) -> 0 | X25: =+W25*100/50 -> 0 | Y25: =+(Q25+M25+X25)/3 -> 0
A26: PROG | C26: Lider-Prog-EV2 | I26: Buscar y representar a AH en alianzas de coordinacion con socios Proy-EV-2 | L26: =+J26-K26 -> 0 | M26: =IFERROR(IF(7<>0, K26*100/J26, IF(J26=K26, K26*100/J26, 0)), 0) -> 0 | P26: =+N26-O26 -> 0 | Q26: =IFERROR(IF(P26<>0, N26*100/O26, IF(N26=O26, N26*100/O26, 0)), 0) -> 0 | W26: =SUM(R26:V26) -> 0 | X26: =+W26*100/50 -> 0 | Y26: =+(Q26+M26+X26)/3 -> 0
A27: PROG | C27: Lider-Prog-EV3 | I27: Buscar y representar a AH en alianzas de coordinacion con socios Proy-EV-3 | L27: =+J27-K27 -> 0 | M27: =IFERROR(IF(7<>0, K27*100/J27, IF(J27=K27, K27*100/J27, 0)), 0) -> 0 | P27: =+N27-O27 -> 0 | Q27: =IFERROR(IF(P27<>0, N27*100/O27, IF(N27=O27, N27*100/O27, 0)), 0) -> 0 | W27: =SUM(R27:V27) -> 0 | X27: =+W27*100/50 -> 0 | Y27: =+(Q27+M27+X27)/3 -> 0
A28: PROT | C28: Lider-Prot-Incid | I28: Buscar y representar a AH en alianzas de coordinacion con socios Proteccion e Inc | L28: =+J28-K28 -> 0 | M28: =IFERROR(IF(7<>0, K28*100/J28, IF(J28=K28, K28*100/J28, 0)), 0) -> 0 | P28: =+N28-O28 -> 0 | Q28: =IFERROR(IF(P28<>0, N28*100/O28, IF(N28=O28, N28*100/O28, 0)), 0) -> 0 | W28: =SUM(R28:V28) -> 0 | X28: =+W28*100/50 -> 0 | Y28: =+(Q28+M28+X28)/3 -> 0
A29: PROG | C29: Lider-Prog-EV1 | I29: Definir contenidos y lineamientos para organizar y coordinar red de madres guia | L29: =+J29-K29 -> 0 | M29: =IFERROR(IF(7<>0, K29*100/J29, IF(J29=K29, K29*100/J29, 0)), 0) -> 0 | P29: =+N29-O29 -> 0 | Q29: =IFERROR(IF(P29<>0, N29*100/O29, IF(N29=O29, N29*100/O29, 0)), 0) -> 0 | W29: =SUM(R29:V29) -> 0 | X29: =+W29*100/50 -> 0 | Y29: =+(Q29+M29+X29)/3 -> 0
A30: PROT | C30: Lider-Prot-Incid | I30: Definir contenidos y lineamientos para organizar y coordinar MPBC | L30: =+J30-K30 -> 0 | M30: =IFERROR(IF(7<>0, K30*100/J30, IF(J30=K30, K30*100/J30, 0)), 0) -> 0 | P30: =+N30-O30 -> 0 | Q30: =IFERROR(IF(P30<>0, N30*100/O30, IF(N30=O30, N30*100/O30, 0)), 0) -> 0 | W30: =SUM(R30:V30) -> 0 | X30: =+W30*100/50 -> 0 | Y30: =+(Q30+M30+X30)/3 -> 0
A31: PROG | C31: Lider-Prog-EV2 | I31: Definir contenidos y lineamientos para organizar y coordinar red Educativa | L31: =+J31-K31 -> 0 | M31: =IFERROR(IF(7<>0, K31*100/J31, IF(J31=K31, K31*100/J31, 0)), 0) -> 0 | P31: =+N31-O31 -> 0 | Q31: =IFERROR(IF(P31<>0, N31*100/O31, IF(N31=O31, N31*100/O31, 0)), 0) -> 0 | W31: =SUM(R31:V31) -> 0 | X31: =+W31*100/50 -> 0 | Y31: =+(Q31+M31+X31)/3 -> 0
A32: PROG | C32: Lider-Prog-EV3 | I32: Definir contenidos y lineamientos para organizar y coordinar red de apoyo juvenil | L32: =+J32-K32 -> 0 | M32: =IFERROR(IF(7<>0, K32*100/J32, IF(J32=K32, K32*100/J32, 0)), 0) -> 0 | P32: =+N32-O32 -> 0 | Q32: =IFERROR(IF(P32<>0, N32*100/O32, IF(N32=O32, N32*100/O32, 0)), 0) -> 0 | W32: =SUM(R32:V32) -> 0 | X32: =+W32*100/50 -> 0 | Y32: =+(Q32+M32+X32)/3 -> 0
A33: PROG | C33: Lider-Prog-EV1 | I33: Elaboracion de material didactico para Proy- EV-1, según Branding | L33: =+J33-K33 -> 0 | M33: =IFERROR(IF(7<>0, K33*100/J33, IF(J33=K33, K33*100/J33, 0)), 0) -> 0 | P33: =+N33-O33 -> 0 | Q33: =IFERROR(IF(P33<>0, N33*100/O33, IF(N33=O33, N33*100/O33, 0)), 0) -> 0 | W33: =SUM(R33:V33) -> 0 | X33: =+W33*100/50 -> 0 | Y33: =+(Q33+M33+X33)/3 -> 0
A34: PROG | C34: Lider-Prog-EV2 | I34: Elaboracion de material didactico para Proy- EV-2, según Branding | L34: =+J34-K34 -> 0 | M34: =IFERROR(IF(7<>0, K34*100/J34, IF(J34=K34, K34*100/J34, 0)), 0) -> 0 | P34: =+N34-O34 -> 0 | Q34: =IFERROR(IF(P34<>0, N34*100/O34, IF(N34=O34, N34*100/O34, 0)), 0) -> 0 | W34: =SUM(R34:V34) -> 0 | X34: =+W34*100/50 -> 0 | Y34: =+(Q34+M34+X34)/3 -> 0
A35: PROG | C35: Lider-Prog-EV3 | I35: Elaboracion de material didactico para Proy- EV-3, según Branding | L35: =+J35-K35 -> 0 | M35: =IFERROR(IF(7<>0, K35*100/J35, IF(J35=K35, K35*100/J35, 0)), 0) -> 0 | P35: =+N35-O35 -> 0 | Q35: =IFERROR(IF(P35<>0, N35*100/O35, IF(N35=O35, N35*100/O35, 0)), 0) -> 0 | W35: =SUM(R35:V35) -> 0 | X35: =+W35*100/50 -> 0 | Y35: =+(Q35+M35+X35)/3 -> 0
A36: PROT | C36: Lider-Prot-Incid | I36: Elaboracion de material didactico para Proteccion e Incidencia según Branding | L36: =+J36-K36 -> 0 | M36: =IFERROR(IF(7<>0, K36*100/J36, IF(J36=K36, K36*100/J36, 0)), 0) -> 0 | P36: =+N36-O36 -> 0 | Q36: =IFERROR(IF(P36<>0, N36*100/O36, IF(N36=O36, N36*100/O36, 0)), 0) -> 0 | W36: =SUM(R36:V36) -> 0 | X36: =+W36*100/50 -> 0 | Y36: =+(Q36+M36+X36)/3 -> 0
A37: PROG | C37: Tecn-Prog-EV-1 | I37: Organizar, coordinar y dar asistencia tecnica a Red de madres guía. | J37: 4 | K37: 4 | L37: =+J37-K37 -> 0 | M37: =IFERROR(IF(7<>0, K37*100/J37, IF(J37=K37, K37*100/J37, 0)), 0) -> 100 | N37: 5 | O37: 5 | P37: =+N37-O37 -> 0 | Q37: =IFERROR(IF(P37<>0, N37*100/O37, IF(N37=O37, N37*100/O37, 0)), 0) -> 100 | R37: 8 | S37: 6 | T37: 6 | U37: 8 | V37: 8 | W37: =SUM(R37:V37) -> 36 | X37: =+W37*100/50 -> 72 | Y37: =+(Q37+M37+X37)/3 -> 90.666667
A38: PROT | B38: PROG | C38: Tecn-Prog-EV-1 | I38: Organizar, capacitar y monitorear plan de acción de los MPBC | L38: =+J38-K38 -> 0 | M38: =IFERROR(IF(7<>0, K38*100/J38, IF(J38=K38, K38*100/J38, 0)), 0) -> 0 | P38: =+N38-O38 -> 0 | Q38: =IFERROR(IF(P38<>0, N38*100/O38, IF(N38=O38, N38*100/O38, 0)), 0) -> 0 | W38: =SUM(R38:V38) -> 0 | X38: =+W38*100/50 -> 0 | Y38: =+(Q38+M38+X38)/3 -> 0
A39: PROG | C39: Tecn-Prog-EV-2 | I39: Organizar, coordinar y dar asistencia tecnica a Red Educativa-APF y docente. | L39: =+J39-K39 -> 0 | M39: =IFERROR(IF(7<>0, K39*100/J39, IF(J39=K39, K39*100/J39, 0)), 0) -> 0 | P39: =+N39-O39 -> 0 | Q39: =IFERROR(IF(P39<>0, N39*100/O39, IF(N39=O39, N39*100/O39, 0)), 0) -> 0 | W39: =SUM(R39:V39) -> 0 | X39: =+W39*100/50 -> 0 | Y39: =+(Q39+M39+X39)/3 -> 0
A40: PROG | C40: Tecn-Prog-EV-3 | I40: Organizar, coordinar y dar asistencia tecnica a Red de Apoyo Juvenil | L40: =+J40-K40 -> 0 | M40: =IFERROR(IF(7<>0, K40*100/J40, IF(J40=K40, K40*100/J40, 0)), 0) -> 0 | P40: =+N40-O40 -> 0 | Q40: =IFERROR(IF(P40<>0, N40*100/O40, IF(N40=O40, N40*100/O40, 0)), 0) -> 0 | W40: =SUM(R40:V40) -> 0 | X40: =+W40*100/50 -> 0 | Y40: =+(Q40+M40+X40)/3 -> 0
A41: PROG | B41: RRHH | C41: Lider-Prog-EV1 | I41: Diseñar e implementar plan de formacion virtual-presencial para ET y red en EV-1 | L41: =+J41-K41 -> 0 | M41: =IFERROR(IF(7<>0, K41*100/J41, IF(J41=K41, K41*100/J41, 0)), 0) -> 0 | P41: =+N41-O41 -> 0 | Q41: =IFERROR(IF(P41<>0, N41*100/O41, IF(N41=O41, N41*100/O41, 0)), 0) -> 0 | W41: =SUM(R41:V41) -> 0 | X41: =+W41*100/50 -> 0 | Y41: =+(Q41+M41+X41)/3 -> 0
A42: PROT | C42: Lider-Prot-Incid | I42: Diseñar e implementar plan de formacion virtual-presencial para ET y MPBC | L42: =+J42-K42 -> 0 | M42: =IFERROR(IF(7<>0, K42*100/J42, IF(J42=K42, K42*100/J42, 0)), 0) -> 0 | P42: =+N42-O42 -> 0 | Q42: =IFERROR(IF(P42<>0, N42*100/O42, IF(N42=O42, N42*100/O42, 0)), 0) -> 0 | W42: =SUM(R42:V42) -> 0 | X42: =+W42*100/50 -> 0 | Y42: =+(Q42+M42+X42)/3 -> 0
A43: PROG | B43: RRHH | C43: Lider-Prog-EV2 | I43: Diseñar e implementar plan de formacion virtual-presencial para ET y Red en EV-2 | L43: =+J43-K43 -> 0 | M43: =IFERROR(IF(7<>0, K43*100/J43, IF(J43=K43, K43*100/J43, 0)), 0) -> 0 | P43: =+N43-O43 -> 0 | Q43: =IFERROR(IF(P43<>0, N43*100/O43, IF(N43=O43, N43*100/O43, 0)), 0) -> 0 | W43: =SUM(R43:V43) -> 0 | X43: =+W43*100/50 -> 0 | Y43: =+(Q43+M43+X43)/3 -> 0
...

Sheet Lista desplegable
A1: Sector | B1: H_Salud | C1: D_Desarrollo_de_la_primera_infancia | D1: U_Educación | E1: R_Protección | F1: L_Medios_de_vida | G1: B_Construyendo_Sostenibilidad | H1: C_Niños_en_crisis | I1: A_Transversal_Incidencia | J1: M_Transversal_Salud_mental | K1: Y_Transversal_Agencia | L1: Z_Administración | M1: X_Patrocinio | N1: ML_Monitoreo | O1: HA_WASH | P1: HB_Nutrición | Q1: HC_Salud_maternoinfantil | R1: HD_Salud_reproductiva | S1: HE__Enfermedad_infecciosa | T1: DA_Cuidado_receptivo | U1: DB_Atención_y_educación_de_la_primera_infancia_en_centros__ECCE | V1: UA_Educación_Holística | W1: UB_Aprendizaje_fundamental | X1: UC_Aprendizaje_socioemocional_(SEL) | Y1: UD_Acceso_y_retención | Z1: RA_Seguridad_en_línea | AA1: RB_Trabajo_infantil | AB1: RC_Prevención_y_respuesta_a_prácticas_nocivas | AC1: RD_Protección_infantil_basada_en_la_comunidad | AD1: LA_Empoderamiento_económico_para_las_familias | AE1: LB_Empoderamiento_económico_para_los_jóvenes | AF1: LC_Seguridad_alimentaria | AG1: BA_Adaptación_climática | AH1: BB_Cuidado_del_medio_ambiente | AI1: BC_Reducción_del_Riesgo_de_Desastres__RRD | AJ1: CA_Niños_desplazados_en_crisis_protegidas | AK1: AA_Incidencia | AL1: MA_Salud_mental_y_apoyo_psicosocial | AM1: YA_Agencia_Infantil_y_Juvenil | AN1: ZA_Gestión_Administrativa | AO1: XA_Gestión_de_Patrocinios | AP1: ML_Monitoreo_y_soporte_técnico_del_programa | AQ1: subsector_code | AR1: subsector_name | AS1: Fuente_de_Financiamiento_ | AT1: Categoría_de_Gastos_ | AU1: type_of_participants | AV1: type_of_activitites | AW1: GFC_Fondo_Global_para_la_Niñez | AX1: GFC | AY1: PMA_Programa_Mundial_de_Alimentos | AZ1: PMA
A2: H_Salud | B2: HA_WASH | C2: DA_Cuidado_receptivo | D2: UA_Educación_Holística | E2: RA_Seguridad_en_línea | F2: LA_Empoderamiento_económico_para_las_familias | G2: BA_Adaptación_climática | H2: CA_Niños_desplazados_en_crisis_protegidas | I2: AA_Incidencia | J2: MA_Salud_mental_y_apoyo_psicosocial | K2: YA_Agencia_Infantil_y_Juvenil | L2: ZA_Gestión_Administrativa | M2: XA_Gestión_de_Patrocinios | N2: ML_Monitoreo_y_soporte_técnico_del_programa | O2: HA011-01_Acceso_a_fuentes_de_agua_potable_segura | P2: HB041-01_Suplementos_nutricionales_para_niños_con_desnutrición_aguda_grave_o_desnutrición_aguda_moderada | Q2: HC061-01_Campañas_de_sensibilización_para_promover_la_prestación_de_servicios_de_salud_y_el_uso_de_profesionales_sanitarios_cualificados | R2: HD091-01_Campañas_de_sensibilización_sobre_la_salud_y_los_derechos_sexuales_y_reproductivos_de_los_jóvenes. | S2: HE121-01_Campañas_de_concienciación_sobre_la_prevención_de_la_malaria_durante_la_temporada_alta | T2: DA141-01_Sesiones_de_capacitación_para_cuidadores_sobre_las_necesidades_y_los_hitos_del_desarrollo_de_la_primera_infancia_en_los_dominios_del_aprendizaje,_la_salud_y_el_bienestar_psicosocial_para_niños_de_0_a_5_años. | U2: DB141-01_Capacitación_para_facilitadores/maestros_del_Centro_ECCE_sobre_las_necesidades,_hitos_y_evaluación_del_desarrollo_de_la_primera_infancia_en_los_dominios_del_aprendizaje,_la_salud_y_el_bienestar_psicosocial. | V2: UA191-01_Maestros_y_facilitadores_capacitados_en_el_currículo_de_Aprendizaje_Socioemocional_(SEL)_y_protección_infantil | W2: UB171-01_Currículos_de_alfabetización_y_aritmética_basados_en_evidencia_identificados_y_adaptados_para_su_uso_en_el_desarrollo_de_currículos_y_materiales | X2: UC191-01_Identificar_y_adaptar_el_contenido_de_aprendizaje_socioemocional_(SEL)_al_contexto_local_y_a_los_grupos_de_edad. | Y2: UD171-01_Rehabilitar_la_infraestructura_escolar_sensible_al_género_y_que_incluya_a_las_personas_con_discapacidad | Z2: RA351-01_Integración_de_actividades_de_aprendizaje_socioemocional_(SEL)_en_entornos_de_aula_relacionados_con_la_promoción_de_la_seguridad_en_línea_para_niños_y_jóvenes | AA2: RB251-01_Proporcionar_habilidades_para_la_vida_apropiadas_para_cada_edad,_alfabetización_financiera_y_capacitación_en_habilidades_vocacionales_integradas_con_habilidades_blandas_y_alfabetización_digital_para_la_transición_de_los_niños_mayores_y_los_jóvenes_al_trabajo_decente. | AB2: RC251-01_Diálogos_comunitarios_para_facilitar_debates_abiertos_con_hombres_y_mujeres_adultos,_ancianos,_líderes_religiosos_y_familias_para_abordar_las_causas_fundamentales_de_las_prácticas_nocivas. | AC2: RD271-01_Sesión_de_concientización_y_taller_de_capacitación_para_niños,_jóvenes,_padres,_líderes_comunitarios_y_voluntarios_sobre_los_derechos_del_niño,_los_principios_de_protección,_la_gestión_de_casos_y_las_vías_de_derivación. | AD2: LA411-01_Transferencia_de_efectivo_para_apoyar_la_compra_de_alimentos_de_los_hogares_con_inseguridad_alimentaria | AE2: LB391-01_Capacitación_modular_en_habilidades_vocacionales,_digitales_y_blandas_(por_ejemplo,_comunicación,_liderazgo,_adaptabilidad) | AF2: LC411-01_Transferencias_de_efectivo_y_vales_para_apoyar_la_compra_de_alimentos_de_hogares_con_inseguridad_alimentaria | AG2: BA441-01_Talleres,_pasantías_y_tutorías_para_que_niños_y_jóvenes_desarrollen_conocimientos_y_habilidades_circulares_verdes_centrándose_en_la_acción_climática,_la_sostenibilidad_y_la_gestión_ambiental. | AH2: BB471-01_Capacitación_de_voluntarios_comunitarios_en_tecnologías_de_energía_renovable_y_de_bajo_consumo_energético_(como_cocinas_de_bajo_consumo_de_combustible_y_otras_fuentes_de_energía_renovable_como_lámparas_solares,_bombas_de_agua_solares,_energía_eólica,_biogás,_energía_hidroeléctrica)_para_reducir_las_emisiones_de_gases_de_efecto_invernadero. | AI2: BC481-01_Talleres_de_evaluación_de_riesgos_y_resiliencia_en_comunidades_objetivo_para_ayudar_en_el_proceso_de_toma_de_decisiones_informadas_sobre_el_riesgo. | AJ2: CA271-01_Planificar_y_mantener_consultas_periódicas_con_las_estructuras_formales_de_protección_infantil_y_migración_(P1.1.1) | AK2: AA501-01_Cabildeo | AL2: MA321-01_Rutinas_estructuradas_y_predecibles_que_integran_actividades_lúdicas,_expresivas_y_socioemocionales_para_promover_la_seguridad_emocional,_la_resiliencia_y_el_desarrollo_cognitivo_y_psicosocial_de_los_niños,_diseñadas_e_implementadas. | AM2: YA231-01_Jóvenes_capacitados_en_liderazgo,_defensa_y_oratoria_para_prepararlos_para_roles_cívicos. | AN2: ZA101-01_Mantenimiento_de_hardware_y_software | AO2: XA101-01_Gestión_de_inscripciones_(incluido_el_análisis) | AP2: MA101-01_Monitoreo_y_seguimiento_continuo | AQ2: HA | AR2: HA_WASH | AS2: 1001-_Patrocinio_ChildFund | AT2: 50101-G.de_personal:Salarios | AU2: Niñez y juventudes | AV2: Formación de Formadores (ToT) | AW2: GFC | AX2: TA214-23-01--Transporte y Alimentacion GFC | AY2: PMA | AZ2: TA213-01-Consultorias-PMA
A3: D_Desarrollo_de_la_primera_infancia | B3: HB_Nutrición | C3: DB_Atención_y_educación_de_la_primera_infancia_en_centros__ECCE | D3: UB_Aprendizaje_fundamental | E3: RB_Trabajo_infantil | F3: LB_Empoderamiento_económico_para_los_jóvenes | G3: BB_Cuidado_del_medio_ambiente | H3: CA_Proteccion_y_respuesta_lideradas _localmente | O3: HA012-01_Esfuerzos_de_promoción_para_promover_el_acceso_a_servicios_de_lavado_y_salud | P3: HB042-01_Rehabilitación_nutricional_comunitaria_para_niños_desnutridos | Q3: HC062-01_Sesiones_de_desarrollo_de_capacidades_para_trabajadores_de_la_salud_y_trabajadores_de_salud_comunitarios_sobre_atención_prenatal,_durante_el_parto_y_posparto | R3: HD092-01_Diálogos_intergeneracionales_sobre_salud_sexual_y_reproductiva_para_padres_y_jóvenes | S3: HE121-02__Talleres_comunitarios_sobre_la_prevención_de_la_malaria_y_el_tratamiento_adecuado_de_la_malaria | T3: DA141-02_Sesión_de_capacitación_para_cuidadores_sobre_cómo_monitorear_el_comportamiento_de_sus_hijos_(de_0_a_5_años)_y_las_habilidades_que_han_adquirido_en_situaciones_cotidianas. | U3: DB141-02_Capacitación_para_facilitadores/maestros_del_Centro_ECCE_sobre_cómo_monitorear_el_comportamiento_de_los_niños_y_las_habilidades_que_han_adquirido_en_situaciones_cotidianas. | V3: UA191-02_Capacitación_de_docentes_sobre_la_incorporación_del_aprendizaje_socioemocional_(SEL)_en_las_lecciones_de_alfabetización_y_aritmética | W3: UB171-02_Libros_de_cuentos_y_materiales_multilingües_para_apoyar_el_aprendizaje_fundamental_desarrollados_y_difundidos_entre_niños_y_adolescentes. | X3: UC191-02_Capacitar_a_docentes_y_facilitadores_en_Aprendizaje_Socioemocional_(SEL)_y_autoprotección | Y3: UD171-02_Defensa_comunitaria_para_la_construcción_y_el_mantenimiento_de_escuelas | Z3: RA351-02_Integración_de_actividades_de_aprendizaje_socioemocional_(SEL)_en_entornos_extracurriculares_relacionados_con_la_promoción_de_la_seguridad_en_línea_para_niños_y_jóvenes | AA3: RB251-02_Capacitar_y_apoyar_a_los_cuidadores_sobre_medios_de_vida_alternativos_para_reducir_la_dependencia_del_trabajo_infantil | AB3: RC251-02_Campañas_de_sensibilización_y_educación_para_jóvenes_y_cuidadores_sobre_las_normas_sociales_que_sustentan_las_prácticas_nocivas_y_las_leyes_nacionales_que_las_prohíben. | AC3: RD271-02_Establecer_y_fortalecer_la_capacidad_de_las_estructuras_formales_e_informales_de_protección_comunitaria_de_la_infancia_(CBCP)_en_materia_de_derechos_del_niño,_principios_de_protección,_gestión_de_casos_y_vías_de_derivación. | AD3: LA412-01_Programa_de_alimentación_escolar | AE3: LB391-02_Sesiones_de_habilidades_para_la_vida_y_planificación_profesional_(incluido_el_desarrollo_y_revisión_de_planes_de_vida) | AF3: LC412-01_Programa_de_alimentación_escolar | AG3: BA441-02_Desarrollo_y_uso_de_módulos_y_aplicaciones_de_aprendizaje_basados_en_dispositivos_móviles_para_el_acceso_continuo_al_conocimiento_entre_niños_y_jóvenes | AH3: BB471-02__Sesiones_de_capacitación_comunitaria_sobre_el_diseño,_la_producción_y_la_instalación/aplicación_de_tecnologías_de_energía_renovable_y_de_bajo_consumo_energético_(como_cocinas_de_bajo_consumo_de_combustible_y_otras_fuentes_de_energía_renovable_como_lámparas_solares,_bombas_de_agua_solares,_energía_eólica,_biogás_e_hidroeléctrica)_para_reducir_las_emisiones_de_gases_de_efecto_invernadero_y_promover_prácticas_energéticas_sostenibles. | AI3: BC481-02_Asistencia_integral_para_salvar_vidas_y_redes_de_seguridad_(incluidos_kits_familiares_de_preparación_para_desastres_personalizados)_durante_y_después_de_la_recuperación_para_las_personas_afectadas_por_desastres:_Asistencia_vital;_albergue,_búsqueda_y_rescate,_asistencia_alimentaria,_agua,_saneamiento_e_higiene_(WASH),_atención_médica,_protección,_salud_mental_y_apoyo_psicosocial._Redes_de_seguridad;_transferencias_de_efectivo,_cupones,_asistencia_alimentaria,_medios_de_vida,_continuidad_educativa,_salud_mental_y_apoyo_psicosocial. | AJ3: CA271-02_Brindar_asistencia_técnica_(ver_definición)_a_los_actores_gubernamentales_en_el_fortalecimiento_del_sistema_de_protección_infantil_(P1.1.2) | AK3: AA501-02_Campaña | AL3: MA321-02_Métodos_de_enseñanza_multisensoriales,_basados_en_el_juego_y_centrados_en_el_alumno_utilizados_por_los_docentes | AM3: YA231-02_Jóvenes_capacitados_sobre_sus_derechos_cívicos,_responsabilidades_y_procesos_democráticos_a_través_de_talleres,_medios_de_comunicación_y_programas_escolares. | AN3: ZA101-02_Servicios_básicos_para_la_implementación_programática | AO3: XA101-02_Gestión_de_información_sobre_niños_matriculados | AP3: MA101-02_Evaluación_de_resultados_de_programas/proyectos | AQ3: HB | AR3: HB_Nutrición | AS3: 1003-_Patrocinio_Local_ChildFund | AT3: 50102-G.de_personal:Beneficio_complem | AU3: Cuidadores | AV3: Actividades locales-Talleres-Formaciones | AX3: TA214-23-02--Material Didactico GFC | AZ3: TA213-02-Incentivo a Voluntarios-PMA
A4: U_Educación | B4: HC_Salud_maternoinfantil | D4: UC_Aprendizaje_socioemocional__SEL | E4: RC_Prevención_y_respuesta_a_prácticas_nocivas | F4: LC_Seguridad_alimentaria | G4: BC_Reducción_del_Riesgo_de_Desastres__RRD | O4: HA021-01_Dotación_de_instalaciones_de_higiene_en_la_comunidad | P4: HB043-01_Monitoreo_del_peso_y_el_crecimiento_y_reporte_de_datos_de_salud_y_nutrición_para_niños_menores_de_6_años | Q4: HC063-01_Kits_esenciales_para_el_parto_y_la_atención_del_recién_nacido_a_los_proveedores_de_atención_médica | R4: HD093-01_Talleres_de_educación_sexual_integral_para_niños_y_niñas | S4: HE122-01_Pruebas_de_diagnóstico_rápido_para_casos_sospechosos_de_malaria | T4: DA151-01_Capacitación_para_cuidadores_sobre_cómo_crear_espacios_seguros_para_el_aprendizaje_en_su_hogar_para_niños_de_0_a_5_años. | U4: DB141-03_Observación_infantil_y_evaluación_del_desarrollo_integradas_en_las_rutinas_diarias_del_centro. | V4: UA191-03__Sesiones_de_coaching_y_aprendizaje_entre_pares_para_docentes_para_reforzar_las_prácticas_de_aprendizaje_socioemocional_(SEL) | W4: UB171-03_Maestros/facilitadores_capacitados_para_crear_materiales_de_enseñanza_y_aprendizaje_de_bajo_costo_y_de_origen_local_para_niños_y_adolescentes | X4: UC191-03_Maestros_y_facilitadores_capacitados_en_el_currículo_de_Aprendizaje_Socioemocional_(SEL)_y_protección_infantil | Y4: UD171-03_Las_comunidades_están_vinculadas_al_financiamiento_y_apoyo_técnico_para_iniciativas_educativas | Z4: RA351-03_Talleres_de_desarrollo_de_capacidades_sobre_habilidades_socioemocionales_relacionadas_con_la_promoción_de_la_seguridad_en_línea_para_niños_y_jóvenes | AA4: RB252-01__Identificación_y_derivación_de_casos_de_trabajo_infantil_(o_abusos_infantiles)_a_los_servicios_de_apoyo_necesarios | AB4: RC252-01_Capacitar_y_equipar_a_legisladores,_agentes_del_orden_y_al_poder_judicial_para_implementar_leyes_sobre_prevención_y_respuesta_a_prácticas_nocivas | AC4: RD272-01_Establecer_sistemas_de_identificación_y_derivación_de_casos,_y_capacitar_a_las_estructuras_de_protección_comunitarias,_a_los_voluntarios_y_líderes_comunitarios_en_el_sistema_de_derivación. | AD4: LA413-01_Distribución_de_alimentos_en_situaciones_de_emergencia | AE4: LB392-01_Cursos_cortos_certificados,_pasantías_estructuradas,_aprendizajes_y_observación_laboral_a_través_de_asociaciones_con_empresas_y_sectores_de_alta_demanda. | AF4: LC413-01_Distribución_de_alimentos_en_situaciones_de_emergencia | AG4: BA441-03_Formación_en_emprendimiento_y_habilidades_vocacionales_para_oportunidades_económicas_verdes,_azules_y_circulares_y_soluciones_basadas_en_la_naturaleza. | AH4: BB471-03_Incentivos_y/o_subsidios_para_que_los_hogares_utilicen_tecnologías/prácticas_de_energía_renovable_y_eficiente_y_sostenible_(como_cocinas_de_bajo_consumo_de_combustible_y_fuentes_de_energía_renovables_como_lámparas_solares,_bombas_de_agua_solares,_biogás,_energía_eólica_e_hidroeléctrica)_para_reducir_las_emisiones_de_gases_de_efecto_invernadero. | AI4: BC482-01_Instalación_de_un_sistema_de_alerta_temprana_basado_en_la_comunidad_para_monitorear_el_desarrollo_de_desastres_(pronosticar_eventos_climáticos_y_meteorológicos_extremos)_en_áreas_de_alto_riesgo. | AJ4: CA271-03_Fortalecer_la_capacidad_profesional_local_para_brindar_servicios_adecuados_de_protección_infantil,_centrados_en_la_gestión_de_casos_y_los_sistemas_de_protección_infantil._(P1.1.3) | AK4: AA501-03_Asociación_y_creación_de_coaliciones | AL4: MA321-03_Maestros_capacitados_en_cuidados_sensibles_al_trauma,_desarrollo_emocional_y_educación_inclusiva | AM4: YA232-01_Participación_de_los_jóvenes_en_el_diseño_e_implementación_de_iniciativas_locales_que_aborden_las_necesidades_de_la_comunidad_(por_ejemplo,_saneamiento,_educación,_acción_climática) | AN4: ZA101-03_Gestión_de_activos_fijos | AO4: XA101-03_Gestión_de_la_desafiliación | AP4: MA101-03_Procesos_de_recopilación_de_datos_de_M&E_(encuesta_global_de_M&E) | AQ4: HC | AR4: HC_Salud_maternoinfantil | AS4: 2001-_Children's_DFCs | AT4: 50103-G.de_personal:imp._de_nomina | AU4: Miembros de la Sociedad Civil | AV4: Actividades, formación-talleres en escuelas/centros | AX4: TA214-23-03--Capacitaciones- GFC | AZ4: TA213-03-Otros Gastos-PMA
A5: R_Protección | B5: HD_Salud_reproductiva | D5: UD_Acceso_y_retención | E5: RD_Protección_infantil_basada_en_la_comunidad | O5: HA031-01_Campañas_de_sensibilización_sobre_higiene_y_saneamiento_en_la_comunidad | P5: HB044-01_Comidas_escolares | Q5: HC071-01_Campañas_de_concienciación_para_promover_el_número_recomendado_de_visitas_prenatales | R5: HD093-02_Talleres_de_educación_sexual_integral_para_padres_y_cuidadores | S5: HE123-01__Suministro_de_mosquiteros_tratados_con_insecticidas_de_larga_duración | T5: DA151-02_Capacitación_para_cuidadores_sobre_cómo_crear_juguetes_hechos_a_mano_y_otros_materiales_de_aprendizaje_en_el_hogar_para_niños_de_0_a_5_años. | U5: DB151-01_Evaluaciones_de_la_calidad_estructural_(las_características_de_los_educadores_y_los_entornos,_como_el_acceso_a_la_formación_y_los_niveles_educativos)_de_los_centros_ECCE | V5: UA191-04_Monitorear_la_integración_del_aprendizaje_socioemocional_(SEL)_a_través_de_observaciones_y_retroalimentación_en_el_aula. | W5: UB172-01_Docentes_capacitados_en_prácticas_instruccionales_y_evaluación_formativa | X5: UC191-04_Capacitación_de_docentes_sobre_la_incorporación_del_aprendizaje_socioemocional_(SEL)_en_las_lecciones_de_alfabetización_y_aritmética | Y5: UD172-01_Actividades_de_promoción_de_programas_de_educación_alternativa_y_actividades_de_enriquecimiento | Z5: RA361-01_Equipar_a_niños_y_jóvenes_con_habilidades_en_tecnologías_de_la_información_y_la_comunicación_(TIC) | AA5: RB253-01_Diálogos_comunitarios_que_involucran_a_padres,_líderes_y_empleadores_sobre_los_daños_del_trabajo_infantil | AB5: RC253-01__Realizar_evaluaciones_de_riesgos_y_denuncia_de_prácticas_nocivas_a_través_de_las_vías_de_derivación_de_protección | AC5: RD281-01_Desarrollar_la_capacidad_de_los_cuidadores_en_materia_de_disciplina_positiva,_comunicación_no_violenta_(positiva),_iniciativas_de_entornos_domésticos_seguros,_desarrollo_infantil_y_para_reconocer_y_responder_a_señales_de_abuso,_negligencia_o_explotación. | AD5: LA414-01_Suministro_de_suministros_(por_ejemplo,_semillas,_fertilizantes,_tracción,_riego,_etc.)_y_capacitación_para_iniciativas_de_huertos_familiares,_aves_de_corral_y_ganado_menor. | AE5: LB401-01_Capacitación_sobre_derechos_laborales,_seguridad_en_el_trabajo_y_prevención_de_la_explotación | AF5: LC414-01_Suministro_de_suministros_(por_ejemplo,_semillas,_fertilizantes,_tracción_con_bueyes,_etc.)_y_capacitación_para_iniciativas_de_huertos_familiares,_aves_de_corral_y_ganado_menor. | AG5: BA442-01_Formación_de_plataformas_dirigidas_por_niños_y_jóvenes,_como_clubes_escolares,_clubes_juveniles,_consejos_juveniles_y_comités_verdes_en_marcos_de_gobernanza_locales,_nacionales_e_internacionales_de_medio_ambiente,_sostenibilidad_y_adaptación_climática. | AH5: BB472-01_Campañas_de_concientización_comunitaria,_talleres_y_sesiones_de_capacitación_sobre_prácticas_sostenibles_de_conservación_del_agua,_como_el_uso_eficiente_del_agua,_la_protección_de_las_fuentes_de_agua,_los_humedales,_la_recolección_de_agua_de_lluvia,_el_reciclaje_de_agua,_etc. | AI5: BC482-02__Servicios_de_información_climática_oportunos_y_basados_en_la_demanda_para_ayudar_en_el_proceso_de_toma_de_decisiones_basadas_en_riesgos:_Servicios_de_información_climática_como_pronósticos_hidrometeorológicos_y_basados_en_impactos_que_incluyen_conocimiento_local_e_indígena_de_(o_información_sobre)_tendencias_e_impactos_climáticos | AJ5: CA272-01_Realizar_sesiones_de_capacitación_para_los_trabajadores_de_primera_línea_(incluido_el_personal_sanitario,_jurídico_y_de_refugios)_sobre_la_identificación_segura_de_problemas_de_protección_infantil,_como_la_trata,_el_abuso,_la_explotación_y_la_negligencia_(P1.2.1) | AK5: AA501-04_Ejecución_de_eventos | AL5: MA322-01_Espacios_seguros_(espacios_amigables_para_los_niños)_creados_en_la_comunidad_para_que_los_cuidadores_y_los_niños_se_reúnan_y_participen_en_actividades_psicosociales_que_incluyen_acciones_grupales_que_adaptan_las_prácticas_de_afrontamiento_locales_y_los_valores_culturales. | AM5: YA233-01_Plataformas_formales_para_jóvenes_(foros_dirigidos_por_jóvenes)_para_abogar_ante_los_responsables_de_políticas,_los_gobiernos_locales,_las_ONG_o_las_instituciones_sobre_políticas_y_cuestiones_que_les_afectan. | AN5: ZA101-04_Salarios_del_personal_administrativo | AO5: XA101-04_Gestión_de_correspondencia | AP5: MA101-04_Salarios_y_beneficios_del_personal_del_programa_(personal_técnico_y_de_implementación) | AQ5: HD | AR5: HD_Salud_reproductiva | AS5: 2002-_DFC_para_Proy./Comm. | AT5: 50104-G.de_personal:_Indemnizacion | AU5: Líderes comunitarios | AV5: Ferias locales o comunitarias | AX5: TA214-23-04--Gastos de Viaje - GFC | AZ5: TA213-04-Salarios y Beneficios-PMA
A6: L_Medios_de_vida | B6: HE__Enfermedad_infecciosa | O6: HA031-02_Campañas_de_sensibilización_sobre_higiene_y_salud_para_niños_en_edad_escolar_y_padres | P6: HB051-01_Talleres_para_padres_sobre_nutrición_y_alimentación_adecuada_para_cuidadores | Q6: HC072-01_Sesiones_de_desarrollo_de_capacidades_para_trabajadores_de_la_salud_y_trabajadores_de_salud_comunitarios_sobre_atención_prenatal,_durante_el_parto_y_posparto | R6: HD094-01_Talleres_sobre_prácticas_pedagógicas_de_educación_sexual_integral_para_educadores | S6: HE124-01_Terapia_de_quimioprevención_de_la_malaria_estacional_durante_la_temporada_de_transmisión | T6: DA151-03_Materiales_de_juego_y_aprendizaje_apropiados_según_la_edad_(para_niños_de_0_a_5_años)_desarrollados_y_distribuidos_para_familias_necesitadas. | U6: DB151-02_Centros_ECCE_que_cumplen_con_estándares_de_calidad_estructural_(por_ejemplo,_las_características_de_los_educadores_y_entornos_como_el_acceso_a_la_capacitación_y_los_niveles_educativos)_abiertos/disponibles_en_las_comunidades. | V6: UA171-01_Docentes_capacitados_en_prácticas_instruccionales_y_evaluación_formativa | W6: UB172-02_Docentes_capacitados_en_metodologías_inclusivas_y_centradas_en_el_niño | X6: UC191-05_Sesiones_de_coaching_y_aprendizaje_entre_pares_para_docentes_para_reforzar_las_prácticas_SEL | Y6: UD172-02_Escuelas_dirigidas_por_la_comunidad_establecidas_en_zonas_marginadas | Z6: RA361-02_Equipar_a_los_docentes_en_el_uso_de_las_tecnologías_de_la_información_y_la_comunicación_(TIC) | AA6: RB254-01_Campañas_de_concientización_sobre_derechos_laborales,_seguridad_en_el_lugar_de_trabajo,_mecanismos_de_denuncia_y_legislación_para_jóvenes,_padres,_cuidadores_y_miembros_de_la_comunidad. | AB6: RC254-01_Defensa_dirigida_por_jóvenes_para_hacer_cumplir_el_desarrollo_y_la_implementación_de_políticas_para_abordar_prácticas_nocivas. | AC6: RD281-02__Difusión_de_mensajes_sobre_prevención_y_protección_contra_la_violencia_dirigidos_a_los_cuidadores | AD6: LA414-02_Capacitación_en_prácticas_agrícolas_sostenibles_(por_ejemplo,_agronomía,_agroecología,_agroforestería,_agricultura_climáticamente_inteligente) | AE6: LB401-02_Campañas_de_concientización_comunitaria_sobre_derechos_laborales_y_empleo_no_explotador | AF6: LC414-02_Capacitación_en_prácticas_agrícolas_sostenibles_(por_ejemplo,_agronomía,_agroecología,_agroforestería,_agricultura_climáticamente_inteligente) | AG6: BA442-02_Inclusión_de_plataformas_lideradas_por_niños_y_jóvenes_en_el_desarrollo_e_implementación_de_planes_de_sostenibilidad,_medio_ambiente,_clima_y_reducción_del_riesgo_de_desastres. | AH6: BB472-02__Esfuerzos_locales_de_conservación_para_implementar_prácticas_sostenibles_de_conservación_del_agua,_como_el_uso_eficiente_del_agua,_la_protección_de_las_fuentes_de_agua,_la_recolección_de_agua_de_lluvia,_la_purificación_de_agua_con_energía_solar,_el_reciclaje_de_agua,_etc. | AI6: BC482-03_Establecimiento_de_sistemas_que_monitoreen_y_evalúen_las_acciones_de_adaptación_de_la_comunidad_a_los_riesgos_de_desastres:_Sistema_que_dé_seguimiento_al_progreso,_identifique_desafíos_y_realice_los_ajustes_necesarios. | AJ6: CA272-02_Desarrollar_y_difundir_vías_de_derivación_fáciles_de_usar_y_procedimientos_operativos_estándar_(POE)_adaptados_a_los_contextos_locales_y_la_dinámica_migratoria_(P1.2.2) | AK6: AA501-05_Análisis_de_políticas_y_presupuestos | AL6: MA323-01_Los_programas_de_educación_ambiental_en_las_escuelas_combinan_la_ciencia_ambiental,_las_prácticas_SEL_(control_emocional,_narración_de_historias_y_desarrollo_de_resiliencia)_y_el_desarrollo_de_resiliencia. | AM6: YA233-02_Espacios_formales_para_que_los_jóvenes_contribuyan_a_los_procesos_de_toma_de_decisiones_a_nivel_comunitario_o_institucional | AN6: ZA101-05_Fortalecimiento_institucional_de_los_socios_locales | AQ6: HE | AR6: HE__Enfermedad_infecciosa | AS6: 2003-_DFCs_locales_para_Children | AT6: 50201-Pago_capacitador-facilitador | AU6: Voluntariados | AV6: Campañas comunitarias | AX6: TA214-23-05--Mejoras Infraestructura- GFC
